<?xml version="1.0" encoding="UTF-8"?>
<!-- Generated by org.testng.reporters.JUnitReportReporter -->
<testsuite skipped="0" hostname="DESKTOP-ENLG37R" name="retry2.Retry1" tests="1" failures="0" timestamp="02 Dec 2023 12:08:42 GMT" time="3.028" errors="1">
  <testcase name="logintest" time="3.028" classname="retry2.Retry1">
    <error type="org.testng.internal.thread.ThreadTimeoutException" message="Method retry2.Retry1.logintest() didn&#039;t finish within the time-out 3000">
      <![CDATA[org.testng.internal.thread.ThreadTimeoutException: Method retry2.Retry1.logintest() didn't finish within the time-out 3000at java.util.concurrent.ThreadPoolExecutor.tryTerminate(Unknown Source)at java.util.concurrent.ThreadPoolExecutor.processWorkerExit(Unknown Source)at java.util.concurrent.ThreadPoolExecutor.runWorker(Unknown Source)at java.util.concurrent.ThreadPoolExecutor$Worker.run(Unknown Source)at java.lang.Thread.run(Unknown Source)]]>
    </error>
  </testcase> <!-- logintest -->
</testsuite> <!-- retry2.Retry1 -->
